Traceback (most recent call last):
  File "/mnt/data/yingxiu/xiuenvs/alpaca3.9/lib/python3.9/site-packages/huggingface_hub/utils/_errors.py", line 259, in hf_raise_for_status
    response.raise_for_status()
  File "/mnt/data/yingxiu/xiuenvs/alpaca3.9/lib/python3.9/site-packages/requests/models.py", line 1021, in raise_for_status
    raise HTTPError(http_error_msg, response=self)
requests.exceptions.HTTPError: 401 Client Error: Unauthorized for url: https://huggingface.co/None/resolve/main/config.json
The above exception was the direct cause of the following exception:
Traceback (most recent call last):
  File "/mnt/data/yingxiu/xiuenvs/alpaca3.9/lib/python3.9/site-packages/transformers/utils/hub.py", line 409, in cached_file
    resolved_file = hf_hub_download(
  File "/mnt/data/yingxiu/xiuenvs/alpaca3.9/lib/python3.9/site-packages/huggingface_hub/utils/_validators.py", line 120, in _inner_fn
    return fn(*args, **kwargs)
  File "/mnt/data/yingxiu/xiuenvs/alpaca3.9/lib/python3.9/site-packages/huggingface_hub/file_download.py", line 1160, in hf_hub_download
    metadata = get_hf_file_metadata(
  File "/mnt/data/yingxiu/xiuenvs/alpaca3.9/lib/python3.9/site-packages/huggingface_hub/utils/_validators.py", line 120, in _inner_fn
    return fn(*args, **kwargs)
  File "/mnt/data/yingxiu/xiuenvs/alpaca3.9/lib/python3.9/site-packages/huggingface_hub/file_download.py", line 1501, in get_hf_file_metadata
    hf_raise_for_status(r)
  File "/mnt/data/yingxiu/xiuenvs/alpaca3.9/lib/python3.9/site-packages/huggingface_hub/utils/_errors.py", line 291, in hf_raise_for_status
    raise RepositoryNotFoundError(message, response) from e
huggingface_hub.utils._errors.RepositoryNotFoundError: 401 Client Error. (Request ID: Root=1-6437f82b-4a348f195a25947d2c1274ab)
Repository Not Found for url: https://huggingface.co/None/resolve/main/config.json.
Please make sure you specified the correct `repo_id` and `repo_type`.
If you are trying to access a private or gated repo, make sure you are authenticated.
Invalid username or password.
During handling of the above exception, another exception occurred:
Traceback (most recent call last):
  File "/mnt/data/yingxiu/LLMCODE/run.py", line 140, in <module>
    fire.Fire(main(args))
  File "/mnt/data/yingxiu/LLMCODE/run.py", line 53, in main
    model = LlamaForCausalLM.from_pretrained(
  File "/mnt/data/yingxiu/xiuenvs/alpaca3.9/lib/python3.9/site-packages/transformers/modeling_utils.py", line 2250, in from_pretrained
    config, model_kwargs = cls.config_class.from_pretrained(
  File "/mnt/data/yingxiu/xiuenvs/alpaca3.9/lib/python3.9/site-packages/transformers/configuration_utils.py", line 546, in from_pretrained
    config_dict, kwargs = cls.get_config_dict(pretrained_model_name_or_path, **kwargs)
  File "/mnt/data/yingxiu/xiuenvs/alpaca3.9/lib/python3.9/site-packages/transformers/configuration_utils.py", line 573, in get_config_dict
    config_dict, kwargs = cls._get_config_dict(pretrained_model_name_or_path, **kwargs)
  File "/mnt/data/yingxiu/xiuenvs/alpaca3.9/lib/python3.9/site-packages/transformers/configuration_utils.py", line 628, in _get_config_dict
    resolved_config_file = cached_file(
  File "/mnt/data/yingxiu/xiuenvs/alpaca3.9/lib/python3.9/site-packages/transformers/utils/hub.py", line 424, in cached_file
    raise EnvironmentError(
OSError: None is not a local folder and is not a valid model identifier listed on 'https://huggingface.co/models'
If this is a private repository, make sure to pass a token having permission to this repo with `use_auth_token` or log in with `huggingface-cli login` and pass `use_auth_token=True`.